<?xml version="1.0"?>
<!-- created with Phobos 1.0.1 "Capricious Choutengan" -->
  <robot name="robot">

    <link name="link_d435_camera">
      <inertial>
        <origin xyz="0 0 0" rpy="0 0 0"/>
        <mass value="0.001"/>
        <inertia ixx="0.001" ixy="0" ixz="0" iyy="0.001" iyz="0" izz="0.001"/>
      </inertial>
      <visual name="d435_camera">
        <origin xyz="0 0 0" rpy="0 0 0"/>
        <geometry>
          <sphere radius="0.00346"/>
        </geometry>
      </visual>
    </link>

    <link name="link_front_left_sonar">
      <inertial>
        <origin xyz="0 0 0" rpy="0 0 0"/>
        <mass value="0.001"/>
        <inertia ixx="0.001" ixy="0" ixz="0" iyy="0.001" iyz="0" izz="0.001"/>
      </inertial>
      <visual name="front_left_sonar">
        <origin xyz="0 0 0" rpy="0 1.5708 0"/>
        <geometry>
          <sphere radius="0.00346"/>
        </geometry>
      </visual>
    </link>

    <link name="link_front_left_wheel">
      <inertial>
        <origin xyz="0 0 0" rpy="0 0 0"/>
        <mass value="7.90271"/>
        <inertia ixx="0.01506" ixy="0" ixz="0" iyy="0.01506" iyz="0" izz="0.02704"/>
      </inertial>
      <visual name="front_left_wheel">
        <origin xyz="0 0 0" rpy="0 0 0"/>
        <geometry>
          <mesh filename="model://UVC_robot_new/meshes/dae/front_left_wheel.dae" scale="0.001 0.001 0.001"/>
        </geometry>
      </visual>
      <collision name="front_left_wheel">
        <origin xyz="0 0.00277 0" rpy="1.5708 0 0"/>
        <geometry>
          <cylinder radius="0.08273" length="0.04836"/>
        </geometry>
      </collision>
    </link>

    <link name="link_front_right_sonar">
      <inertial>
        <origin xyz="0 0 0" rpy="0 0 0"/>
        <mass value="0.001"/>
        <inertia ixx="0.001" ixy="0" ixz="0" iyy="0.001" iyz="0" izz="0.001"/>
      </inertial>
      <visual name="front_right_sonar">
        <origin xyz="0 0 0" rpy="0 1.5708 0"/>
        <geometry>
          <sphere radius="0.00346"/>
        </geometry>
      </visual>
    </link>

    <link name="link_front_right_wheel">
      <inertial>
        <origin xyz="0 0 0" rpy="0 0 0"/>
        <mass value="7.90462"/>
        <inertia ixx="0.01507" ixy="0" ixz="0" iyy="0.01507" iyz="0" izz="0.02706"/>
      </inertial>
      <visual name="front_right_wheel">
        <origin xyz="0 0 0" rpy="0 0 0"/>
        <geometry>
          <mesh filename="model://UVC_robot_new/meshes/dae/front_right_wheel.dae" scale="0.001 0.001 0.001"/>
        </geometry>
      </visual>
      <collision name="front_right_wheel">
        <origin xyz="0 -0.00277 0" rpy="1.5708 0 0"/>
        <geometry>
          <cylinder radius="0.08274" length="0.04836"/>
        </geometry>
      </collision>
    </link>

    <link name="link_realsense_t265">
      <inertial>
        <origin xyz="0 0 0" rpy="0 0 0"/>
        <mass value="0.001"/>
        <inertia ixx="0.001" ixy="0" ixz="0" iyy="0.001" iyz="0" izz="0.001"/>
      </inertial>
      <visual name="realsense_t265">
        <origin xyz="0 0 0" rpy="0 0 -3.14156"/>
        <geometry>
          <mesh filename="model://UVC_robot_new/meshes/dae/realsense_t265.dae" scale="0.001 0.001 0.001"/>
        </geometry>
      </visual>
      <collision name="realsense_t265">
        <origin xyz="0 0 0" rpy="-3.14159 1.5708 0"/>
        <geometry>
          <box size="0.024 0.108 0.013"/>
        </geometry>
      </collision>
    </link>

    <link name="link_rear_left_wheel">
      <inertial>
        <origin xyz="0 0 0" rpy="0 0 0"/>
        <mass value="2.20995"/>
        <inertia ixx="0.00166" ixy="0" ixz="0" iyy="0.00166" iyz="0" izz="0.00284"/>
      </inertial>
      <visual name="rear_left_wheel">
        <origin xyz="0 0 0" rpy="0 0 0"/>
        <geometry>
          <mesh filename="model://UVC_robot_new/meshes/dae/rear_left_wheel.dae" scale="0.001 0.001 0.001"/>
        </geometry>
      </visual>
      <collision name="rear_left_wheel">
        <origin xyz="-3e-05 0 0" rpy="1.5708 0 0"/>
        <geometry>
          <cylinder radius="0.05072" length="0.03598"/>
        </geometry>
      </collision>
    </link>

    <link name="link_rear_left_wrist">
      <inertial>
        <origin xyz="0 0 0" rpy="0 0 0"/>
        <mass value="2.0"/>
        <inertia ixx="2e-05" ixy="0" ixz="0" iyy="2e-05" iyz="0" izz="2e-05"/>
      </inertial>
      <visual name="rear_left_wrist">
        <origin xyz="0 0 0" rpy="0 0 0"/>
        <geometry>
          <mesh filename="model://UVC_robot_new/meshes/dae/rear_left_wrist.dae" scale="0.001 0.001 0.001"/>
        </geometry>
      </visual>
    </link>

    <link name="link_rear_right_wheel">
      <inertial>
        <origin xyz="0 0 0" rpy="0 0 0"/>
        <mass value="2.21293"/>
        <inertia ixx="0.00166" ixy="0" ixz="0" iyy="0.00166" iyz="0" izz="0.00285"/>
      </inertial>
      <visual name="rear_right_wheel">
        <origin xyz="0 0 0" rpy="0 0 0"/>
        <geometry>
          <mesh filename="model://UVC_robot_new/meshes/dae/rear_right_wheel.dae" scale="0.001 0.001 0.001"/>
        </geometry>
      </visual>
      <collision name="rear_right_wheel">
        <origin xyz="-3e-05 0 0" rpy="1.5708 0 0"/>
        <geometry>
          <cylinder radius="0.05074" length="0.036"/>
        </geometry>
      </collision>
    </link>

    <link name="link_rear_right_wrist">
      <inertial>
        <origin xyz="0 0 0" rpy="0 0 0"/>
        <mass value="2.0"/>
        <inertia ixx="2e-05" ixy="0" ixz="0" iyy="2e-05" iyz="0" izz="2e-05"/>
      </inertial>
      <visual name="rear_right_wrist">
        <origin xyz="0 0 0" rpy="0 0 0"/>
        <geometry>
          <mesh filename="model://UVC_robot_new/meshes/dae/rear_right_wrist.dae" scale="0.001 0.001 0.001"/>
        </geometry>
      </visual>
    </link>

    <link name="link_rear_sonar">
      <inertial>
        <origin xyz="0 0 0" rpy="0 0 0"/>
        <mass value="0.001"/>
        <inertia ixx="0.001" ixy="0" ixz="0" iyy="0.001" iyz="0" izz="0.001"/>
      </inertial>
      <visual name="rear_sonar">
        <origin xyz="0 0 0" rpy="0 0 -3.14159"/>
        <geometry>
          <sphere radius="0.00346"/>
        </geometry>
      </visual>
    </link>

    <link name="link_side_left_sonar">
      <inertial>
        <origin xyz="0 0 0" rpy="0 0 0"/>
        <mass value="0.001"/>
        <inertia ixx="0.001" ixy="0" ixz="0" iyy="0.001" iyz="0" izz="0.001"/>
      </inertial>
      <visual name="side_left_sonar">
        <origin xyz="0 0 0" rpy="1.5708 0 0"/>
        <geometry>
          <sphere radius="0.00346"/>
        </geometry>
      </visual>
    </link>

    <link name="link_side_right_sonar">
      <inertial>
        <origin xyz="0 0 0" rpy="0 0 0"/>
        <mass value="0.001"/>
        <inertia ixx="0.001" ixy="0" ixz="0" iyy="0.001" iyz="0" izz="0.001"/>
      </inertial>
      <visual name="side_right_sonar">
        <origin xyz="0 0 0" rpy="-1.5708 0 0"/>
        <geometry>
          <sphere radius="0.00346"/>
        </geometry>
      </visual>
    </link>

    <link name="link_t265_camera_fisheye">
      <inertial>
        <origin xyz="0 0 0" rpy="0 0 0"/>
        <mass value="0.001"/>
        <inertia ixx="0.001" ixy="0" ixz="0" iyy="0.001" iyz="0" izz="0.001"/>
      </inertial>
      <visual name="t265_camera_fisheye">
        <origin xyz="0 0 0" rpy="0 0 0"/>
        <geometry>
          <sphere radius="0.00346"/>
        </geometry>
      </visual>
    </link>

    <link name="link_t265_camera_gyro">
      <inertial>
        <origin xyz="0 0 0" rpy="0 0 0"/>
        <mass value="0.001"/>
        <inertia ixx="0.001" ixy="0" ixz="0" iyy="0.001" iyz="0" izz="0.001"/>
      </inertial>
      <visual name="t265_camera_gyro">
        <origin xyz="0 0 0" rpy="0 0 0"/>
        <geometry>
          <sphere radius="0.00346"/>
        </geometry>
      </visual>
    </link>

    <link name="link_t265_camera_odom">
      <inertial>
        <origin xyz="0 0 0" rpy="0 0 0"/>
        <mass value="0.001"/>
        <inertia ixx="0.001" ixy="0" ixz="0" iyy="0.001" iyz="0" izz="0.001"/>
      </inertial>
      <visual name="t265_camera_odom">
        <origin xyz="0 0 0" rpy="0 0 0"/>
        <geometry>
          <sphere radius="0.00346"/>
        </geometry>
      </visual>
    </link>

    <link name="link_uvc_lights">
      <inertial>
        <origin xyz="0 0 0" rpy="0 0 0"/>
        <mass value="0.001"/>
        <inertia ixx="0.001" ixy="0" ixz="0" iyy="0.001" iyz="0" izz="0.001"/>
      </inertial>
      <visual name="light_1">
        <origin xyz="-0.10432 -0.07221 0.64035" rpy="0 0 0"/>
        <geometry>
          <cylinder radius="0.01004" length="1.32715"/>
        </geometry>
        <material name="UVC"/>
      </visual>
      <visual name="light_2">
        <origin xyz="-0.10432 0.07284 0.64035" rpy="0 0 0"/>
        <geometry>
          <cylinder radius="0.01004" length="1.32715"/>
        </geometry>
        <material name="UVC"/>
      </visual>
      <visual name="light_3">
        <origin xyz="0.0941 0.1377 0.64035" rpy="0 0 0"/>
        <geometry>
          <cylinder radius="0.01004" length="1.32715"/>
        </geometry>
        <material name="UVC"/>
      </visual>
      <visual name="light_4">
        <origin xyz="-0.02265 0.1377 0.64035" rpy="0 0 0"/>
        <geometry>
          <cylinder radius="0.01004" length="1.32715"/>
        </geometry>
        <material name="UVC"/>
      </visual>
      <visual name="light_5">
        <origin xyz="0.0941 -0.14053 0.64035" rpy="0 0 0"/>
        <geometry>
          <cylinder radius="0.01004" length="1.32715"/>
        </geometry>
        <material name="UVC"/>
      </visual>
      <visual name="light_6">
        <origin xyz="-0.02265 -0.14053 0.64035" rpy="0 0 0"/>
        <geometry>
          <cylinder radius="0.01004" length="1.32715"/>
        </geometry>
        <material name="UVC"/>
      </visual>
    </link>

    <link name="link_virofighter">
      <inertial>
        <origin xyz="0 0 0" rpy="0 0 0"/>
        <mass value="10.011"/>
        <inertia ixx="13.2077" ixy="0" ixz="0" iyy="13.3744" iyz="0" izz="0.34275"/>
      </inertial>
      <visual name="virofighter">
        <origin xyz="-0.25 0 0.049" rpy="0 0 0"/>
        <geometry>
          <mesh filename="model://UVC_robot_new/meshes/dae/virofighter.dae" scale="1.0 1.0 1.0"/>
        </geometry>
      </visual>
      <collision name="virofighter">
        <origin xyz="-0.22008 0.00079 1.00857" rpy="0 0 0"/>
        <geometry>
          <mesh filename="model://UVC_robot_new/meshes/dae/Cube.019.dae" scale="1.0 1.0 1.0"/>
        </geometry>
      </collision>
    </link>

    <joint name="joint_d435_camera" type="fixed">
      <origin xyz="0.04512 0 1.77259" rpy="0 1.0472 0"/>
      <parent link="link_virofighter"/>
      <child link="link_d435_camera"/>
    </joint>

    <joint name="joint_front_left_sonar" type="fixed">
      <origin xyz="0.08 -0.1293 0.2115" rpy="0 0 0"/>
      <parent link="link_virofighter"/>
      <child link="link_front_left_sonar"/>
    </joint>

    <joint name="joint_front_left_wheel" type="continuous">
      <origin xyz="0 -0.17827 0.082" rpy="0 0 0"/>
      <parent link="link_virofighter"/>
      <child link="link_front_left_wheel"/>
      <axis xyz="0 1.0 0"/>
      <dynamics damping="0.005" friction="0.005" />
    </joint>

    <joint name="joint_front_right_sonar" type="fixed">
      <origin xyz="0.08 0.1337 0.21166" rpy="0 0 0"/>
      <parent link="link_virofighter"/>
      <child link="link_front_right_sonar"/>
    </joint>

    <joint name="joint_front_right_wheel" type="continuous">
      <origin xyz="0 0.17827 0.082" rpy="0 0 0"/>
      <parent link="link_virofighter"/>
      <child link="link_front_right_wheel"/>
      <axis xyz="0 1.0 0"/>
      <dynamics damping="0.005" friction="0.005" />
    </joint>

    <joint name="joint_realsense_t265" type="fixed">
      <origin xyz="-0.52457 0 0.42892" rpy="0 0 0"/>
      <parent link="link_virofighter"/>
      <child link="link_realsense_t265"/>
    </joint>

    <joint name="joint_rear_left_wheel" type="continuous">
      <origin xyz="0.03802 0 -0.08" rpy="0 0 0"/>
      <parent link="link_rear_left_wrist"/>
      <child link="link_rear_left_wheel"/>
      <axis xyz="0 1.0 0"/>
      <dynamics damping="0.005" friction="0.005" />
    </joint>

    <joint name="joint_rear_left_wrist" type="continuous">
      <origin xyz="-0.47 -0.16211 0.13" rpy="0 0 0"/>
      <parent link="link_virofighter"/>
      <child link="link_rear_left_wrist"/>
      <axis xyz="0 0 1.0"/>
      <dynamics damping="0.005" friction="0.005" />
    </joint>

    <joint name="joint_rear_right_sonar" type="fixed">
      <origin xyz="-0.54 0.01302 0.33103" rpy="0 0 3.14159"/>
      <parent link="link_virofighter"/>
      <child link="link_rear_sonar"/>
    </joint>

    <joint name="joint_rear_right_wheel" type="continuous">
      <origin xyz="0.03802 0 -0.08" rpy="0 0 0"/>
      <parent link="link_rear_right_wrist"/>
      <child link="link_rear_right_wheel"/>
      <axis xyz="0 1.0 0"/>
      <dynamics damping="0.005" friction="0.005" />
    </joint>

    <joint name="joint_rear_right_wrist" type="continuous">
      <origin xyz="-0.47 0.16211 0.13" rpy="0 0 0"/>
      <parent link="link_virofighter"/>
      <child link="link_rear_right_wrist"/>
      <axis xyz="0 0 1.0"/>
      <dynamics damping="0.005" friction="0.005" />
    </joint>

    <joint name="joint_side_left_sonar" type="fixed">
      <origin xyz="-0.34701 -0.215 0.21154" rpy="0 0 -1.5708"/>
      <parent link="link_virofighter"/>
      <child link="link_side_left_sonar"/>
    </joint>

    <joint name="joint_side_right_sonar" type="fixed">
      <origin xyz="-0.34701 0.215 0.21154" rpy="0 0 1.5708"/>
      <parent link="link_virofighter"/>
      <child link="link_side_right_sonar"/>
    </joint>

    <joint name="joint_t265_camera_fisheye" type="fixed">
      <origin xyz="-0.01319 0.03438 0.00069" rpy="0 0 0"/>
      <parent link="link_realsense_t265"/>
      <child link="link_t265_camera_fisheye"/>
    </joint>

    <joint name="joint_t265_camera_gyro" type="fixed">
      <origin xyz="-0.01319 -0.031 0.00069" rpy="0 0 0"/>
      <parent link="link_realsense_t265"/>
      <child link="link_t265_camera_gyro"/>
    </joint>

    <joint name="joint_t265_camera_odom" type="fixed">
      <origin xyz="-0.01319 0.00169 0.00069" rpy="0 0 0"/>
      <parent link="link_realsense_t265"/>
      <child link="link_t265_camera_odom"/>
    </joint>

    <joint name="link_uvc_lights" type="fixed">
      <origin xyz="-0.3361 0 0.52606" rpy="0 0 0"/>
      <parent link="link_virofighter"/>
      <child link="link_uvc_lights"/>
    </joint>

    <material name="UVC">
      <color rgba="0.48542 0.30838 0.8 1.0"/>
    </material>

<!--  
  Bemásolni minden axis alá:
  	<dynamics damping="0.005" friction="0.005" />
-->

    <!-- D435 realsense kamera -->
    <gazebo reference="link_d435_camera">
      <sensor name='camera' type='depth'>
        <update_rate>10</update_rate>
        <camera name='__default__'>
          <horizontal_fov>1.0472</horizontal_fov>
          <image>
	    <width>640</width>
	    <height>480</height>
	    <format>R8G8B8</format>
          </image>
          <clip>
	    <near>0.05</near>
	    <far>3</far>
          </clip>
        </camera>
        <plugin name='camera_plugin' filename='libuvcrobot_openni_kinect.so'>
          <baseline>0.2</baseline>
          <alwaysOn>1</alwaysOn>
          <updateRate>0.0</updateRate>
          <cameraName>camera_ir</cameraName>
          <imageTopicName>/d435/color/image_raw</imageTopicName>
          <cameraInfoTopicName>/d435/color/camera_info</cameraInfoTopicName>
          <depthImageTopicName>/d435/depth/image_rect_raw</depthImageTopicName>
          <depthImageCameraInfoTopicName>/d435/depth/camera_info</depthImageCameraInfoTopicName>
          <pointCloudTopicName>/d435/depth/color/points</pointCloudTopicName>
          <frameName>d435_link</frameName>
          <pointCloudCutoff>0.5</pointCloudCutoff>
          <pointCloudCutoffMax>3.0</pointCloudCutoffMax>
          <distortionK1>0</distortionK1>
          <distortionK2>0</distortionK2>
          <distortionK3>0</distortionK3>
          <distortionT1>0</distortionT1>
          <distortionT2>0</distortionT2>
          <CxPrime>0</CxPrime>
          <Cx>0</Cx>
          <Cy>0</Cy>
          <focalLength>0</focalLength>
          <hackBaseline>0</hackBaseline>
        </plugin>
      </sensor>
    </gazebo>

    <!-- Realsense t265 fisheye -->
    <gazebo reference="link_t265_camera_fisheye">
      <sensor name="camera" type="wideanglecamera">
        <camera>
          <horizontal_fov>6.283</horizontal_fov>
          <image>
	    <width>800</width>
	    <height>848</height>
          </image>
          <clip>
	    <near>0.1</near>
	    <far>100</far>
          </clip>
          <lens>
	    <type>custom</type>
	    <custom_function>
	      <c1>1.05</c1>
	      <c2>4</c2>
	      <f>1.0</f>
	      <fun>tan</fun>
	    </custom_function>
	    <scale_to_hfov>true</scale_to_hfov>
	    <cutoff_angle>3.1415</cutoff_angle>
	    <env_texture_size>512</env_texture_size>
          </lens>
          <always_on>true</always_on>
          <update_rate>30</update_rate>
        </camera>
        <plugin name="camera_controller" filename="libgazebo_ros_camera.so">
          <alwaysOn>true</alwaysOn>
          <updateRate>30</updateRate>
          <cameraName>t265_camera</cameraName>
          <imageTopicName>/t265/fisheye/image_raw</imageTopicName>
          <cameraInfoTopicName>/t265/fisheye/camera_info</cameraInfoTopicName>
          <frameName>t265_link</frameName>
          <hackBaseline>0.07</hackBaseline>
          <distortionK1>-0.007419134024530649</distortionK1>
          <distortionK2>0.041209351271390915</distortionK2>
          <distortionK3>-0.03811917081475258</distortionK3>
          <distortionT1>0.006366158835589886</distortionT1>
          <distortionT2>0.0</distortionT2>
          <CxPrime>416.00531005859375</CxPrime>
          <Cx>16.00531005859375</Cx>
          <Cy>403.38909912109375</Cy>
        </plugin>
      </sensor>
    </gazebo>

    <!-- Realsense t265 gyro -->
    <gazebo reference="link_t265_camera_gyro">
      <gravity>true</gravity>
      <sensor name="t265_camera_imu" type="imu">
        <always_on>true</always_on>
        <update_rate>30</update_rate>
        <visualize>false</visualize>
        <plugin filename="libgazebo_ros_imu_sensor.so" name="imu_plugin">
          <topicName>/t265/gyro/sample</topicName>
          <bodyName>link_t265_camera_gyro</bodyName>
          <updateRateHZ>30</updateRateHZ>
          <gaussianNoise>0.000001</gaussianNoise>
          <xyzOffset>0 0 0</xyzOffset>
          <rpyOffset>0 0 0</rpyOffset>
          <frameName>t265_link</frameName>
        </plugin>
      </sensor>
    </gazebo>

    <!-- Realsense t265 odometry -->
    <gazebo>
      <plugin name="p3d_base_controller" filename="libgazebo_ros_p3d.so">
        <alwaysOn>true</alwaysOn>
        <updateRate>30</updateRate>
        <bodyName>link_t265_camera_odom</bodyName>
        <topicName>/t265/odom/sample</topicName>
        <gaussianNoise>0.001</gaussianNoise>
        <frameName>odom</frameName>
        <xyzOffsets>0 0 0</xyzOffsets>
        <rpyOffsets>0 0 0</rpyOffsets>
      </plugin>
    </gazebo>

    <!-- Ultrasonic rear-->
    <gazebo reference="link_rear_sonar">
      <sensor type="ray" name="sonar">
        <pose>0 0 0 0 0 0</pose>
        <visualize>true</visualize>
        <update_rate>5</update_rate>
        <ray>
          <scan>
            <horizontal>
              <samples>5</samples>
              <resolution>1.0</resolution>
              <min_angle>-0.25</min_angle>
              <max_angle>0.25</max_angle>
            </horizontal>
            <vertical>
              <samples>5</samples>
              <resolution>1</resolution>
              <min_angle>-0.25</min_angle>
              <max_angle>0.25</max_angle>
            </vertical>
          </scan>
          <range>
            <min>0.01</min>
            <max>0.75</max>
            <resolution>0.01</resolution>
          </range>
        </ray>
        <plugin filename="libgazebo_ros_range.so" name="gazebo_ros_range">
          <gaussianNoise>0.005</gaussianNoise>
          <alwaysOn>true</alwaysOn>
          <updateRate>5</updateRate>
          <topicName>/ultrasound/rear</topicName>
          <frameName>rear</frameName>
          <fov>0.5</fov>
          <radiation>ultrasound</radiation>
        </plugin>
      </sensor>
    </gazebo>
    
    <!-- Ultrasonic side left-->
    <gazebo reference="link_side_left_sonar">
      <sensor type="ray" name="sonar">
        <pose>0 0 0 0 0 0</pose>
        <visualize>true</visualize>
        <update_rate>5</update_rate>
        <ray>
          <scan>
            <horizontal>
              <samples>5</samples>
              <resolution>1.0</resolution>
              <min_angle>-0.25</min_angle>
              <max_angle>0.25</max_angle>
            </horizontal>
            <vertical>
              <samples>5</samples>
              <resolution>1</resolution>
              <min_angle>-0.25</min_angle>
              <max_angle>0.25</max_angle>
            </vertical>
          </scan>
          <range>
            <min>0.01</min>
            <max>0.75</max>
            <resolution>0.01</resolution>
          </range>
        </ray>
        <plugin filename="libgazebo_ros_range.so" name="gazebo_ros_range">
          <gaussianNoise>0.005</gaussianNoise>
          <alwaysOn>true</alwaysOn>
          <updateRate>5</updateRate>
          <topicName>/ultrasound/left</topicName>
          <frameName>left</frameName>
          <fov>0.5</fov>
          <radiation>ultrasound</radiation>
        </plugin>
      </sensor>
    </gazebo>
    
    <!-- Ultrasonic side right-->
    <gazebo reference="link_side_right_sonar">
      <sensor type="ray" name="sonar">
        <pose>0 0 0 0 0 0</pose>
        <visualize>true</visualize>
        <update_rate>5</update_rate>
        <ray>
          <scan>
            <horizontal>
              <samples>5</samples>
              <resolution>1.0</resolution>
              <min_angle>-0.25</min_angle>
              <max_angle>0.25</max_angle>
            </horizontal>
            <vertical>
              <samples>5</samples>
              <resolution>1</resolution>
              <min_angle>-0.25</min_angle>
              <max_angle>0.25</max_angle>
            </vertical>
          </scan>
          <range>
            <min>0.01</min>
            <max>0.75</max>
            <resolution>0.01</resolution>
          </range>
        </ray>
        <plugin filename="libgazebo_ros_range.so" name="gazebo_ros_range">
          <gaussianNoise>0.005</gaussianNoise>
          <alwaysOn>true</alwaysOn>
          <updateRate>5</updateRate>
          <topicName>/ultrasound/right</topicName>
          <frameName>right</frameName>
          <fov>0.5</fov>
          <radiation>ultrasound</radiation>
        </plugin>
      </sensor>
    </gazebo>
    
    <!-- Ultrasonic front left-->
    <gazebo reference="link_front_left_sonar">
      <sensor type="ray" name="sonar">
        <pose>0 0 0 0 0 0</pose>
        <visualize>true</visualize>
        <update_rate>5</update_rate>
        <ray>
          <scan>
            <horizontal>
              <samples>5</samples>
              <resolution>1.0</resolution>
              <min_angle>-0.25</min_angle>
              <max_angle>0.25</max_angle>
            </horizontal>
            <vertical>
              <samples>5</samples>
              <resolution>1</resolution>
              <min_angle>-0.25</min_angle>
              <max_angle>0.25</max_angle>
            </vertical>
          </scan>
          <range>
            <min>0.01</min>
            <max>0.75</max>
            <resolution>0.01</resolution>
          </range>
        </ray>
        <plugin filename="libgazebo_ros_range.so" name="gazebo_ros_range">
          <gaussianNoise>0.005</gaussianNoise>
          <alwaysOn>true</alwaysOn>
          <updateRate>5</updateRate>
          <topicName>/ultrasound/front_left</topicName>
          <frameName>front_left</frameName>
          <fov>0.5</fov>
          <radiation>ultrasound</radiation>
        </plugin>
      </sensor>
    </gazebo>

  <!-- Ultrasonic front right-->
    <gazebo reference="link_front_right_sonar">
      <sensor type="ray" name="sonar">
        <pose>0 0 0 0 0 0</pose>
        <visualize>true</visualize>
        <update_rate>5</update_rate>
        <ray>
          <scan>
            <horizontal>
              <samples>5</samples>
              <resolution>1.0</resolution>
              <min_angle>-0.25</min_angle>
              <max_angle>0.25</max_angle>
            </horizontal>
            <vertical>
              <samples>5</samples>
              <resolution>1</resolution>
              <min_angle>-0.25</min_angle>
              <max_angle>0.25</max_angle>
            </vertical>
          </scan>
          <range>
            <min>0.01</min>
            <max>0.75</max>
            <resolution>0.01</resolution>
          </range>
        </ray>
        <plugin filename="libgazebo_ros_range.so" name="gazebo_ros_range">
          <gaussianNoise>0.005</gaussianNoise>
          <alwaysOn>true</alwaysOn>
          <updateRate>5</updateRate>
          <topicName>/ultrasound/front_right</topicName>
          <frameName>front_right</frameName>
          <fov>0.5</fov>
          <radiation>ultrasound</radiation>
        </plugin>
      </sensor>
    </gazebo>
    
    <!-- Differential drive -->
    <gazebo>
      <plugin name='differential_drive_controller' filename='libgazebo_ros_diff_drive.so'>
        <alwaysOn>1</alwaysOn>
        <updateRate>100</updateRate>
        <leftJoint>joint_front_right_wheel</leftJoint>
        <rightJoint>joint_front_left_wheel</rightJoint>
        <wheelSeparation>0.36</wheelSeparation>
        <wheelDiameter>0.17</wheelDiameter>
        <wheelTorque>10</wheelTorque>
        <commandTopic>/cmd_vel</commandTopic>
        <odometryTopic>/robot/fusion/odometry</odometryTopic>
        <odometryFrame>odom</odometryFrame>
        <publishOdomTF>true</publishOdomTF>
        <robotBaseFrame>base_link</robotBaseFrame>
        <robotNamespace>/</robotNamespace>
      </plugin>
    </gazebo>

  </robot>
