<?xml version="1.0" ?>
<sdf version='1.7'>
  <model name='uvc1_virofighter'>
    <pose>0 0 0 0 -0 0</pose>
    <link name='base_footprint'/>
    <link name='base_link'>
      <inertial>
        <pose>0 0 0 0 -0 0</pose>
        <mass>10.011</mass>
        <inertia>
          <ixx>13.2077</ixx>
          <ixy>0</ixy>
          <ixz>0</ixz>
          <iyy>13.3744</iyy>
          <iyz>0</iyz>
          <izz>0.34275</izz>
        </inertia>
      </inertial>
      <collision name='base_collision'>
        <pose>-0.25 0 0.049 0 -0 0</pose>
        <geometry>
          <mesh>
            <uri>model://uvc1_common/meshes/bases/Cube.019.dae</uri>
            <scale>1 1 1</scale>
          </mesh>
        </geometry>
      </collision>
      <visual name='base_visual'>
        <pose>-0.25 0 0.049 0 -0 0</pose>
        <geometry>
          <mesh>
            <uri>model://uvc1_common/meshes/bases/virofighter_base.dae</uri>
            <scale>1 1 1</scale>
          </mesh>
        </geometry>
        <material>
          <ambient>1 1 1 1</ambient>
          <diffuse>1 1 1 1</diffuse>
        </material>
      </visual>
    </link>
    <joint name='wheel_front_left_joint' type='revolute'>
      <parent>base_link</parent>
      <child>wheel_front_left_link</child>
      <pose>0 -0.17827 0.082 0 -0 0</pose>
      <axis>
        <xyz>0 1 0</xyz>
        <dynamics>
          <damping>0.005</damping>
          <friction>0.005</friction>
          <spring_reference>0</spring_reference>
          <spring_stiffness>0</spring_stiffness>
        </dynamics>
        <limit>
          <lower>-1e+16</lower>
          <upper>1e+16</upper>
        </limit>
      </axis>
    </joint>
    <link name='wheel_front_left_link'>
      <inertial>
        <pose>0 0 0 0 -0 0</pose>
        <mass>7.90271</mass>
        <inertia>
          <ixx>0.01506</ixx>
          <ixy>0</ixy>
          <ixz>0</ixz>
          <iyy>0.01506</iyy>
          <iyz>0</iyz>
          <izz>0.02704</izz>
        </inertia>
      </inertial>
      <collision name='wheel_front_left_collision'>
        <pose>0 0.00277 0 1.5708 -0 0</pose>
        <geometry>
          <cylinder>
            <radius>0.08273</radius>
            <length>0.04836</length>
          </cylinder>
        </geometry>
      </collision>
      <visual name='wheel_front_left_visual'>
        <pose>0 0 0 0 -0 0</pose>
        <geometry>
          <mesh>
            <uri>model://uvc1_common/meshes/wheels/wheel_front_left.dae</uri>
            <scale>0.001 0.001 0.001</scale>
          </mesh>
        </geometry>
        <material>
          <ambient>0 0 0 1</ambient>
          <diffuse>0 0 0 1</diffuse>
        </material>
      </visual>
    </link>
    <joint name='wheel_front_right_joint' type='revolute'>
      <parent>base_link</parent>
      <child>wheel_front_right_link</child>
      <pose>0 0.17827 0.082 0 -0 0</pose>
      <axis>
        <xyz>0 1 0</xyz>
        <dynamics>
          <damping>0.005</damping>
          <friction>0.005</friction>
          <spring_reference>0</spring_reference>
          <spring_stiffness>0</spring_stiffness>
        </dynamics>
        <limit>
          <lower>-1e+16</lower>
          <upper>1e+16</upper>
        </limit>
      </axis>
    </joint>
    <link name='wheel_front_right_link'>
      <inertial>
        <pose>0 0 0 0 -0 0</pose>
        <mass>7.90462</mass>
        <inertia>
          <ixx>0.01507</ixx>
          <ixy>0</ixy>
          <ixz>0</ixz>
          <iyy>0.01507</iyy>
          <iyz>0</iyz>
          <izz>0.02706</izz>
        </inertia>
      </inertial>
      <collision name='wheel_front_right_collision'>
        <pose>0 -0.00277 0 1.5708 -0 0</pose>
        <geometry>
          <cylinder>
            <radius>0.08274</radius>
            <length>0.04836</length>
          </cylinder>
        </geometry>
      </collision>
      <visual name='wheel_front_right_visual'>
        <pose>0 0 0 0 -0 0</pose>
        <geometry>
          <mesh>
            <uri>model://uvc1_common/meshes/wheels/wheel_front_right.dae</uri>
            <scale>0.001 0.001 0.001</scale>
          </mesh>
        </geometry>
        <material>
          <ambient>0 0 0 1</ambient>
          <diffuse>0 0 0 1</diffuse>
        </material>
      </visual>
    </link>
    <joint name='wrist_rear_left_joint' type='revolute'>
      <parent>base_link</parent>
      <child>wrist_rear_left_link</child>
      <pose>-0.47 -0.16211 0.13 0 -0 0</pose>
      <axis>
        <xyz>0 0 1</xyz>
        <dynamics>
          <damping>0.005</damping>
          <friction>0.005</friction>
          <spring_reference>0</spring_reference>
          <spring_stiffness>0</spring_stiffness>
        </dynamics>
        <limit>
          <lower>-1e+16</lower>
          <upper>1e+16</upper>
        </limit>
      </axis>
    </joint>
    <link name='wrist_rear_left_link'>
      <inertial>
        <pose>0 0 0 0 -0 0</pose>
        <mass>2</mass>
        <inertia>
          <ixx>2e-05</ixx>
          <ixy>0</ixy>
          <ixz>0</ixz>
          <iyy>2e-05</iyy>
          <iyz>0</iyz>
          <izz>2e-05</izz>
        </inertia>
      </inertial>
      <visual name='rear_left_wrist_visual'>
        <pose>0 0 0 0 -0 0</pose>
        <geometry>
          <mesh>
            <uri>model://uvc1_common/meshes/wheels/wrist_rear_left.dae</uri>
            <scale>0.001 0.001 0.001</scale>
          </mesh>
        </geometry>
        <material>
          <ambient>0.8706 0.8118 0.7647 1</ambient>
          <diffuse>0.8706 0.8118 0.7647 1</diffuse>
        </material>
      </visual>
    </link>
    <joint name='wheel_rear_left_joint' type='revolute'>
      <parent>wrist_rear_left_link</parent>
      <child>wheel_rear_left_link</child>
      <pose>0.03802 0 -0.08 0 -0 0</pose>
      <axis>
        <xyz>0 1 0</xyz>
        <dynamics>
          <damping>0.005</damping>
          <friction>0.005</friction>
          <spring_reference>0</spring_reference>
          <spring_stiffness>0</spring_stiffness>
        </dynamics>
        <limit>
          <lower>-1e+16</lower>
          <upper>1e+16</upper>
        </limit>
      </axis>
    </joint>
    <link name='wheel_rear_left_link'>
      <inertial>
        <pose>0 0 0 0 -0 0</pose>
        <mass>2.20995</mass>
        <inertia>
          <ixx>0.00166</ixx>
          <ixy>0</ixy>
          <ixz>0</ixz>
          <iyy>0.00166</iyy>
          <iyz>0</iyz>
          <izz>0.00284</izz>
        </inertia>
      </inertial>
      <collision name='rear_left_wheel_collision'>
        <pose>-3e-05 0 0 1.5708 -0 0</pose>
        <geometry>
          <cylinder>
            <radius>0.05072</radius>
            <length>0.03598</length>
          </cylinder>
        </geometry>
      </collision>
      <visual name='wheel_rear_left_visual'>
        <pose>0 0 0 0 -0 0</pose>
        <geometry>
          <mesh>
            <uri>model://uvc1_common/meshes/wheels/wheel_rear_left.dae</uri>
            <scale>0.001 0.001 0.001</scale>
          </mesh>
        </geometry>
        <material>
          <ambient>0 0 0 1</ambient>
          <diffuse>0 0 0 1</diffuse>
        </material>
      </visual>
    </link>
    <joint name='wrist_rear_right_joint' type='revolute'>
      <parent>base_link</parent>
      <child>wrist_rear_right_link</child>
      <pose>-0.47 0.16211 0.13 0 -0 0</pose>
      <axis>
        <xyz>0 0 1</xyz>
        <dynamics>
          <damping>0.005</damping>
          <friction>0.005</friction>
          <spring_reference>0</spring_reference>
          <spring_stiffness>0</spring_stiffness>
        </dynamics>
        <limit>
          <lower>-1e+16</lower>
          <upper>1e+16</upper>
        </limit>
      </axis>
    </joint>
    <link name='wrist_rear_right_link'>
      <inertial>
        <pose>0 0 0 0 -0 0</pose>
        <mass>2</mass>
        <inertia>
          <ixx>2e-05</ixx>
          <ixy>0</ixy>
          <ixz>0</ixz>
          <iyy>2e-05</iyy>
          <iyz>0</iyz>
          <izz>2e-05</izz>
        </inertia>
      </inertial>
      <visual name='rear_right_wrist_visual'>
        <pose>0 0 0 0 -0 0</pose>
        <geometry>
          <mesh>
            <uri>model://uvc1_common/meshes/wheels/wrist_rear_right.dae</uri>
            <scale>0.001 0.001 0.001</scale>
          </mesh>
        </geometry>
        <material>
          <ambient>0.8706 0.8118 0.7647 1</ambient>
          <diffuse>0.8706 0.8118 0.7647 1</diffuse>
        </material>
      </visual>
    </link>
    <joint name='wheel_rear_right_joint' type='revolute'>
      <parent>wrist_rear_right_link</parent>
      <child>wheel_rear_right_link</child>
      <pose>0.03802 0 -0.08 0 -0 0</pose>
      <axis>
        <xyz>0 1 0</xyz>
        <dynamics>
          <damping>0.005</damping>
          <friction>0.005</friction>
          <spring_reference>0</spring_reference>
          <spring_stiffness>0</spring_stiffness>
        </dynamics>
        <limit>
          <lower>-1e+16</lower>
          <upper>1e+16</upper>
        </limit>
      </axis>
    </joint>
    <link name='wheel_rear_right_link'>
      <inertial>
        <pose>0 0 0 0 -0 0</pose>
        <mass>2.20995</mass>
        <inertia>
          <ixx>0.00166</ixx>
          <ixy>0</ixy>
          <ixz>0</ixz>
          <iyy>0.00166</iyy>
          <iyz>0</iyz>
          <izz>0.00284</izz>
        </inertia>
      </inertial>
      <collision name='rear_right_wheel_collision'>
        <pose>-3e-05 0 0 1.5708 -0 0</pose>
        <geometry>
          <cylinder>
            <radius>0.05072</radius>
            <length>0.03598</length>
          </cylinder>
        </geometry>
      </collision>
      <visual name='wheel_rear_right_visual'>
        <pose>0 0 0 0 -0 0</pose>
        <geometry>
          <mesh>
            <uri>model://uvc1_common/meshes/wheels/wheel_rear_right.dae</uri>
            <scale>0.001 0.001 0.001</scale>
          </mesh>
        </geometry>
        <material>
          <ambient>0 0 0 1</ambient>
          <diffuse>0 0 0 1</diffuse>
        </material>
      </visual>
    </link>
    <link name='camera_d455_link'>
      <visual name='d455_visual'>
        <pose>0 0 0 0 0 -3.14156</pose>
        <geometry>
          <mesh>
            <uri>model://uvc1_common/meshes/sensors/camera_d455.stl</uri>
            <scale>0.001 0.001 0.001</scale>
          </mesh>
        </geometry>
      </visual>
      <collision name='camera_d455_collision'>
        <pose>0 0 0 3e-06 1.57079 3.14159</pose>
        <geometry>
          <box>
            <size>0.124 0.029 0.025</size>
          </box>
        </geometry>
      </collision>
      <inertial>
        <pose>0 0 0 0 -0 0</pose>
        <mass>0.159</mass>
        <inertia>
          <ixx>1.2e-05</ixx>
          <ixy>0</ixy>
          <ixz>0</ixz>
          <iyy>0.00021</iyy>
          <iyz>0</iyz>
          <izz>0.00022</izz>
        </inertia>
      </inertial>
      <sensor name='d455_rgb' type='camera'>
        <pose>0 0 0 0 -0 0</pose>
        <always_on>1</always_on>
        <visualize>1</visualize>
        <update_rate>30</update_rate>
        <camera>
          <horizontal_fov>1.5</horizontal_fov>
          <image>
            <width>1280</width>
            <height>800</height>
            <format>R8G8B8</format>
          </image>
          <clip>
            <near>0.05</near>
            <far>20</far>
          </clip>
        </camera>
        <plugin name='d455_rgb_camera_controller' filename='libgazebo_ros_camera.so'>
          <ros>
            <namespace>/d455/rgb</namespace>
          </ros>
          <frame_name>camera_d455_color_optical_frame</frame_name>
          <image_topic_name>/d455/color/image_raw</image_topic_name>
          <camera_info_topic_name>/d455/color/camera_info</camera_info_topic_name>
        </plugin>
      </sensor>
      <sensor name='d455_depth' type='depth'>
        <pose>0 0 0 0 -0 0</pose>
        <always_on>1</always_on>
        <visualize>1</visualize>
        <update_rate>30</update_rate>
        <camera>
          <horizontal_fov>1.52</horizontal_fov>
          <depth_camera>
            <clip>
              <near>0.6</near>
              <far>6</far>
            </clip>
            <output>depths</output>
          </depth_camera>
          <image>
            <width>1280</width>
            <height>720</height>
            <format>R8G8B8</format>
          </image>
          <clip>
            <near>0.1</near>
            <far>100</far>
          </clip>
        </camera>
        <plugin name='d455_depth_camera_controller' filename='libgazebo_ros_depth_camera.so'>
          <ros>
            <namespace>/d455/depth</namespace>
          </ros>
          <frame_name>camera_d455_depth_optical_frame</frame_name>
          <depth_image_topic_name>/d455/depth/image_raw</depth_image_topic_name>
          <point_cloud_topic_name>/d455/depth/points</point_cloud_topic_name>
          <depth_image_camera_info_topic_name>/d455/depth/camera_info</depth_image_camera_info_topic_name>
          <point_cloud>1</point_cloud>
        </plugin>
      </sensor>
      <sensor name='d455_imu' type='imu'>
        <pose>0 0 0 0 -0 0</pose>
        <always_on>1</always_on>
        <update_rate>200</update_rate>
        <plugin name='d455_imu_controller' filename='libgazebo_ros_imu_sensor.so'>
          <ros>
            <namespace>/d455/imu</namespace>
          </ros>
          <frame_name>camera_d455_imu_frame</frame_name>
          <topic_name>/d455/imu/data_raw</topic_name>
          <gaussian_noise>0.0005</gaussian_noise>
        </plugin>
      </sensor>
    </link>
    <joint name='camera_d455_joint' type='fixed'>
      <parent>base_link</parent>
      <child>camera_d455_link</child>
      <pose>-0.52457 0 0.42892 0 -0 0</pose>
    </joint>
    <link name='camera_d455_color_optical_frame'/>
    <joint name='camera_d455_color_optical_joint' type='fixed'>
      <parent>camera_d455_link</parent>
      <child>camera_d455_color_optical_frame</child>
      <pose>0 0 0 3.14159 -1.57079 3.14159</pose>
    </joint>
    <link name='camera_d455_depth_optical_frame'/>
    <joint name='camera_d455_depth_optical_joint' type='fixed'>
      <parent>camera_d455_link</parent>
      <child>camera_d455_depth_optical_frame</child>
      <pose>0 0 0 3.14159 -1.57079 3.14159</pose>
    </joint>
    <link name='camera_d455_imu_frame'/>
    <joint name='camera_d455_imu_joint' type='fixed'>
      <parent>camera_d455_link</parent>
      <child>camera_d455_imu_frame</child>
      <pose>0 0 0 0 -0 0</pose>
    </joint>
    <link name='camera_d435i_link'>
      <visual name='d435i_visual'>
        <pose>0 0 0 0 -0 0</pose>
        <geometry>
          <mesh>
            <uri>model://uvc1_common/meshes/sensors/camera_d435i.dae</uri>
            <scale>1 1 1</scale>
          </mesh>
        </geometry>
      </visual>
      <collision name='d435i_collision'>
        <pose>0 0 0 0 -0 0</pose>
        <geometry>
          <box>
            <size>0.09 0.025 0.025</size>
          </box>
        </geometry>
      </collision>
      <inertial>
        <pose>0 0 0 0 -0 0</pose>
        <mass>0.072</mass>
        <inertia>
          <ixx>6.25e-05</ixx>
          <ixy>0</ixy>
          <ixz>0</ixz>
          <iyy>7e-05</iyy>
          <iyz>0</iyz>
          <izz>7e-05</izz>
        </inertia>
      </inertial>
      <sensor name='d435i_rgb' type='camera'>
        <pose>0 0 0 0 -0 0</pose>
        <always_on>1</always_on>
        <update_rate>30</update_rate>
        <camera>
          <horizontal_fov>1.2</horizontal_fov>
          <image>
            <width>1920</width>
            <height>1080</height>
            <format>R8G8B8</format>
          </image>
          <clip>
            <near>0.05</near>
            <far>20</far>
          </clip>
        </camera>
        <plugin name='d435i_rgb_plugin' filename='libgazebo_ros_camera.so'>
          <ros>
            <namespace>/d435i</namespace>
          </ros>
          <frame_name>camera_d435i_color_optical_frame</frame_name>
          <image_topic_name>/d435i/color/image_raw</image_topic_name>
          <camera_info_topic_name>/d435i/color/camera_info</camera_info_topic_name>
        </plugin>
      </sensor>
      <sensor name='d435i_depth' type='depth'>
        <pose>0 0 0 0 -0 0</pose>
        <always_on>1</always_on>
        <update_rate>30</update_rate>
        <camera>
          <horizontal_fov>1.52</horizontal_fov>
          <image>
            <width>1280</width>
            <height>720</height>
            <format>R8G8B8</format>
          </image>
          <clip>
            <near>0.1</near>
            <far>4</far>
          </clip>
        </camera>
        <plugin name='d435i_depth_plugin' filename='libgazebo_ros_depth_camera.so'>
          <ros>
            <namespace>/d435i</namespace>
          </ros>
          <frame_name>camera_d435i_depth_optical_frame</frame_name>
          <depth_image_topic_name>/d435i/depth/image_raw</depth_image_topic_name>
          <point_cloud_topic_name>/d435i/depth/points</point_cloud_topic_name>
          <depth_image_camera_info_topic_name>/d435i/depth/camera_info</depth_image_camera_info_topic_name>
          <point_cloud>1</point_cloud>
        </plugin>
      </sensor>
      <sensor name='d435i_imu' type='imu'>
        <pose>0 0 0 0 -0 0</pose>
        <always_on>1</always_on>
        <update_rate>150</update_rate>
        <plugin name='d435i_imu_plugin' filename='libgazebo_ros_imu_sensor.so'>
          <ros>
            <namespace>/d435i</namespace>
          </ros>
          <frame_name>camera_d435i_imu_frame</frame_name>
          <topic_name>/d435i/imu/data_raw</topic_name>
          <gaussian_noise>0.0005</gaussian_noise>
        </plugin>
      </sensor>
    </link>
    <joint name='camera_d435i_joint' type='fixed'>
      <parent>base_link</parent>
      <child>camera_d435i_link</child>
      <pose>0.04512 0 1.77259 0 1.0472 0</pose>
    </joint>
    <link name='camera_d435i_color_optical_frame'/>
    <joint name='camera_d435i_color_optical_joint' type='fixed'>
      <parent>camera_d435i_link</parent>
      <child>camera_d435i_color_optical_frame</child>
      <pose>0 0 0 3.14159 -1.57079 3.14159</pose>
    </joint>
    <link name='camera_d435i_depth_optical_frame'/>
    <joint name='camera_d435i_depth_optical_joint' type='fixed'>
      <parent>camera_d435i_link</parent>
      <child>camera_d435i_depth_optical_frame</child>
      <pose>0 0 0 3.14159 -1.57079 3.14159</pose>
    </joint>
    <link name='camera_d435i_imu_frame'/>
    <joint name='camera_d435i_imu_joint' type='fixed'>
      <parent>camera_d435i_link</parent>
      <child>camera_d435i_imu_frame</child>
      <pose>0 0 0 0 -0 0</pose>
    </joint>
    <link name='ultrasonic_front_left_link'>
      <visual name='front_left_sonar'>
        <pose>0 0 0 3.14159 1.57079 3.14159</pose>
        <geometry>
          <sphere>
            <radius>0.00346</radius>
          </sphere>
        </geometry>
      </visual>
      <inertial>
        <pose>0 0 0 0 -0 0</pose>
        <mass>0.01</mass>
        <inertia>
          <ixx>1e-06</ixx>
          <ixy>0</ixy>
          <ixz>0</ixz>
          <iyy>1e-06</iyy>
          <iyz>0</iyz>
          <izz>1e-06</izz>
        </inertia>
      </inertial>
      <sensor name='ultrasonic_front_left' type='ray'>
        <pose>0 0 0 0 -0 0</pose>
        <always_on>1</always_on>
        <visualize>1</visualize>
        <update_rate>5</update_rate>
        <ray>
          <scan>
            <horizontal>
              <samples>5</samples>
              <resolution>1</resolution>
              <min_angle>-0.25</min_angle>
              <max_angle>0.25</max_angle>
            </horizontal>
            <vertical>
              <samples>5</samples>
              <resolution>1</resolution>
              <min_angle>-0.25</min_angle>
              <max_angle>0.25</max_angle>
            </vertical>
          </scan>
          <range>
            <min>0.01</min>
            <max>0.75</max>
            <resolution>0.01</resolution>
          </range>
        </ray>
        <plugin name='ultrasonic_front_left_controller' filename='libgazebo_ros_ray_sensor.so'>
          <ros>
            <namespace>/ultrasound/front_left</namespace>
          </ros>
          <frame_name>ultrasonic_front_left_link</frame_name>
          <output_type>sensor_msgs/Range</output_type>
          <gaussianNoise>0.005</gaussianNoise>
        </plugin>
      </sensor>
    </link>
    <joint name='ultrasonic_front_left_joint' type='fixed'>
      <parent>base_link</parent>
      <child>ultrasonic_front_left_link</child>
      <pose>0.08 -0.1293 0.2115 0 -0 0</pose>
    </joint>
    <link name='ultrasonic_front_right_link'>
      <visual name='front_right_sonar'>
        <pose>0 0 0 3.14159 1.57079 3.14159</pose>
        <geometry>
          <sphere>
            <radius>0.00346</radius>
          </sphere>
        </geometry>
      </visual>
      <inertial>
        <pose>0 0 0 0 -0 0</pose>
        <mass>0.01</mass>
        <inertia>
          <ixx>1e-06</ixx>
          <ixy>0</ixy>
          <ixz>0</ixz>
          <iyy>1e-06</iyy>
          <iyz>0</iyz>
          <izz>1e-06</izz>
        </inertia>
      </inertial>
      <sensor name='ultrasonic_front_right' type='ray'>
        <pose>0 0 0 0 -0 0</pose>
        <always_on>1</always_on>
        <visualize>1</visualize>
        <update_rate>5</update_rate>
        <ray>
          <scan>
            <horizontal>
              <samples>5</samples>
              <resolution>1</resolution>
              <min_angle>-0.25</min_angle>
              <max_angle>0.25</max_angle>
            </horizontal>
            <vertical>
              <samples>5</samples>
              <resolution>1</resolution>
              <min_angle>-0.25</min_angle>
              <max_angle>0.25</max_angle>
            </vertical>
          </scan>
          <range>
            <min>0.01</min>
            <max>0.75</max>
            <resolution>0.01</resolution>
          </range>
        </ray>
        <plugin name='ultrasonic_front_right_controller' filename='libgazebo_ros_ray_sensor.so'>
          <ros>
            <namespace>/ultrasound/front_right</namespace>
          </ros>
          <frame_name>ultrasonic_front_right_link</frame_name>
          <output_type>sensor_msgs/Range</output_type>
          <gaussianNoise>0.005</gaussianNoise>
        </plugin>
      </sensor>
    </link>
    <joint name='ultrasonic_front_right_joint' type='fixed'>
      <parent>base_link</parent>
      <child>ultrasonic_front_right_link</child>
      <pose>0.08 0.1337 0.21166 0 -0 0</pose>
    </joint>
    <link name='ultrasonic_side_left_link'>
      <visual name='side_left_sonar'>
        <pose>0 0 0 1.5708 -0 0</pose>
        <geometry>
          <sphere>
            <radius>0.00346</radius>
          </sphere>
        </geometry>
      </visual>
      <inertial>
        <pose>0 0 0 0 -0 0</pose>
        <mass>0.01</mass>
        <inertia>
          <ixx>1e-06</ixx>
          <ixy>0</ixy>
          <ixz>0</ixz>
          <iyy>1e-06</iyy>
          <iyz>0</iyz>
          <izz>1e-06</izz>
        </inertia>
      </inertial>
      <sensor name='ultrasonic_side_left' type='ray'>
        <pose>0 0 0 0 -0 0</pose>
        <always_on>1</always_on>
        <visualize>1</visualize>
        <update_rate>5</update_rate>
        <ray>
          <scan>
            <horizontal>
              <samples>5</samples>
              <resolution>1</resolution>
              <min_angle>-0.25</min_angle>
              <max_angle>0.25</max_angle>
            </horizontal>
            <vertical>
              <samples>5</samples>
              <resolution>1</resolution>
              <min_angle>-0.25</min_angle>
              <max_angle>0.25</max_angle>
            </vertical>
          </scan>
          <range>
            <min>0.01</min>
            <max>0.75</max>
            <resolution>0.01</resolution>
          </range>
        </ray>
        <plugin name='ultrasonic_side_left_controller' filename='libgazebo_ros_ray_sensor.so'>
          <ros>
            <namespace>/ultrasound/left</namespace>
          </ros>
          <frame_name>ultrasonic_side_left_link</frame_name>
          <output_type>sensor_msgs/Range</output_type>
          <gaussianNoise>0.005</gaussianNoise>
        </plugin>
      </sensor>
    </link>
    <joint name='ultrasonic_side_left_joint' type='fixed'>
      <parent>base_link</parent>
      <child>ultrasonic_side_left_link</child>
      <pose>-0.34701 -0.215 0.21154 0 0 -1.5708</pose>
    </joint>
    <link name='ultrasonic_side_right_link'>
      <visual name='side_right_sonar'>
        <pose>0 0 0 -1.5708 0 0</pose>
        <geometry>
          <sphere>
            <radius>0.00346</radius>
          </sphere>
        </geometry>
      </visual>
      <inertial>
        <pose>0 0 0 0 -0 0</pose>
        <mass>0.01</mass>
        <inertia>
          <ixx>1e-06</ixx>
          <ixy>0</ixy>
          <ixz>0</ixz>
          <iyy>1e-06</iyy>
          <iyz>0</iyz>
          <izz>1e-06</izz>
        </inertia>
      </inertial>
      <sensor name='ultrasonic_side_right' type='ray'>
        <pose>0 0 0 0 -0 0</pose>
        <always_on>1</always_on>
        <visualize>1</visualize>
        <update_rate>5</update_rate>
        <ray>
          <scan>
            <horizontal>
              <samples>5</samples>
              <resolution>1</resolution>
              <min_angle>-0.25</min_angle>
              <max_angle>0.25</max_angle>
            </horizontal>
            <vertical>
              <samples>5</samples>
              <resolution>1</resolution>
              <min_angle>-0.25</min_angle>
              <max_angle>0.25</max_angle>
            </vertical>
          </scan>
          <range>
            <min>0.01</min>
            <max>0.75</max>
            <resolution>0.01</resolution>
          </range>
        </ray>
        <plugin name='ultrasonic_side_right_controller' filename='libgazebo_ros_ray_sensor.so'>
          <ros>
            <namespace>/ultrasound/right</namespace>
          </ros>
          <frame_name>ultrasonic_side_right_link</frame_name>
          <output_type>sensor_msgs/Range</output_type>
          <gaussianNoise>0.005</gaussianNoise>
        </plugin>
      </sensor>
    </link>
    <joint name='ultrasonic_side_right_joint' type='fixed'>
      <parent>base_link</parent>
      <child>ultrasonic_side_right_link</child>
      <pose>-0.34701 0.215 0.21154 0 -0 1.5708</pose>
    </joint>
    <link name='ultrasonic_rear_link'>
      <visual name='rear_sonar'>
        <pose>0 0 0 0 0 -3.14159</pose>
        <geometry>
          <sphere>
            <radius>0.00346</radius>
          </sphere>
        </geometry>
      </visual>
      <inertial>
        <pose>0 0 0 0 -0 0</pose>
        <mass>0.01</mass>
        <inertia>
          <ixx>1e-06</ixx>
          <ixy>0</ixy>
          <ixz>0</ixz>
          <iyy>1e-06</iyy>
          <iyz>0</iyz>
          <izz>1e-06</izz>
        </inertia>
      </inertial>
      <sensor name='ultrasonic_rear' type='ray'>
        <pose>0 0 0 0 -0 0</pose>
        <always_on>1</always_on>
        <visualize>1</visualize>
        <update_rate>5</update_rate>
        <ray>
          <scan>
            <horizontal>
              <samples>5</samples>
              <resolution>1</resolution>
              <min_angle>-0.25</min_angle>
              <max_angle>0.25</max_angle>
            </horizontal>
            <vertical>
              <samples>5</samples>
              <resolution>1</resolution>
              <min_angle>-0.25</min_angle>
              <max_angle>0.25</max_angle>
            </vertical>
          </scan>
          <range>
            <min>0.01</min>
            <max>0.75</max>
            <resolution>0.01</resolution>
          </range>
        </ray>
        <plugin name='ultrasonic_rear_controller' filename='libgazebo_ros_ray_sensor.so'>
          <ros>
            <namespace>/ultrasound/rear</namespace>
          </ros>
          <frame_name>ultrasonic_rear_link</frame_name>
          <output_type>sensor_msgs/Range</output_type>
          <gaussianNoise>0.005</gaussianNoise>
        </plugin>
      </sensor>
    </link>
    <joint name='ultrasonic_rear_joint' type='fixed'>
      <parent>base_link</parent>
      <child>ultrasonic_rear_link</child>
      <pose>-0.54 0.01302 0.33103 0 -0 3.14159</pose>
    </joint>
    <plugin name='uvc1_diff_drive' filename='libgazebo_ros_diff_drive.so'>
      <ros>
        <namespace>/</namespace>
      </ros>
      <left_joint>wheel_front_left_joint</left_joint>
      <right_joint>wheel_front_right_joint</right_joint>
      <wheel_separation>0.356</wheel_separation>
      <wheel_diameter>0.165</wheel_diameter>
      <max_wheel_torque>20</max_wheel_torque>
      <update_rate>100</update_rate>
      <command_topic>cmd_vel</command_topic>
      <publish_odom>1</publish_odom>
      <publish_odom_tf>1</publish_odom_tf>
      <odometry_topic>odom</odometry_topic>
      <robot_base_frame>base_footprint</robot_base_frame>
    </plugin>
    <plugin name='uvc1_joint_state' filename='libgazebo_ros_joint_state_publisher.so'>
      <ros>
        <remapping>~/out:=joint_states</remapping>
      </ros>
      <update_rate>30</update_rate>
      <joint_name>wheel_front_left_joint</joint_name>
      <joint_name>wheel_front_right_joint</joint_name>
      <joint_name>wheel_rear_left_joint</joint_name>
      <joint_name>wheel_rear_right_joint</joint_name>
    </plugin>
  </model>
</sdf>
