<?xml version="1.0" ?>
<sdf version='1.7'>
  <model name='uvc1_virofighter'>

    <!-- ============================= -->
    <!-- Base_Footprint_Fixed_Joint_Lump -->
    <!-- ============================= -->
    <link name='base_footprint'>

      <inertial>
        <pose>-0.035763 1.6e-05 0.067205 0 -0 0</pose>
        <mass>11.232</mass>
        <inertia>
          <ixx>13.8027</ixx>
          <ixy>6.05581e-05</ixy>
          <ixz>0.180382</ixz>
          <iyy>14.1077</iyy>
          <iyz>-4.09128e-05</iyz>
          <izz>0.485685</izz>
        </inertia>
      </inertial>

      <!-- base_footprint_fixed_joint_lump__base_collision_collision -->
      <!-- base_footprint_fixed_joint_lump__base_visual_visual -->
      <collision name='base_collision'>
        <pose>-0.25 0 1 0 -0 0</pose>
        <geometry>
          <mesh>
            <scale>1 1 1</scale>
            <uri>model://uvc1_common/meshes/bases/Cube.019.dae</uri>
          </mesh>
        </geometry>
      </collision>

      <visual name='base_visual'>
        <pose>-0.25 0 0.049 0 -0 0</pose>
        <geometry>
          <mesh>
            <scale>1 1 1</scale>
            <uri>model://uvc1_common/meshes/bases/virofighter_base.dae</uri>
          </mesh>
        </geometry>
      </visual>

      <!--base_footprint_fixed_joint_lump__camera_d455_collision_collision_2 -->
      <!--base_footprint_fixed_joint_lump__d455_visual_visual_2 -->
      <collision name='camera_d455_collision_2'>
        <pose>-0.52457 0 0.42892 -3.14159 1.5708 0</pose>
        <geometry>
          <box>
            <size>0.124 0.029 0.025</size>
          </box>
        </geometry>
      </collision>

      <visual name='d455_visual_visual_2'>
        <pose>-0.52457 0 0.42892 0 0 -3.14156</pose>
        <geometry>
          <box>
            <size>0.124 0.029 0.025</size>
          </box>
        </geometry>
      </visual>

      <!--camera_d455_rgb sensor gazebo plugin-->
      <sensor name='d455_rgb' type='camera'>
        <always_on>1</always_on>
        <visualize>1</visualize>
        <update_rate>30</update_rate>
        <pose>-0.52457 0 0.42892 0 -0 0</pose>

        <camera>
          <horizontal_fov>1.5</horizontal_fov>
          <image><width>1280</width><height>800</height><format>R8G8B8</format></image>
          <clip><near>0.05</near><far>20</far></clip>
        </camera>

        <plugin name='d455_rgb_camera_controller' filename='libgazebo_ros_camera.so'>
          <ros><namespace>/d455/rgb</namespace></ros>
          <frame_name>camera_d455_color_optical_frame</frame_name>
          <image_topic_name>/d455/color/image_raw</image_topic_name>
          <camera_info_topic_name>/d455/color/camera_info</camera_info_topic_name>
        </plugin>
      </sensor>

      
      <!--camera_d455_depth sensor gazebo plugin-->
      <sensor name='d455_depth' type='camera'>
        <always_on>1</always_on>
        <visualize>1</visualize>
        <update_rate>30</update_rate>
        <pose>-0.52457 0 0.42892 0 -0 0</pose>

        <camera>
          <horizontal_fov>1.52</horizontal_fov>
          <depth_camera><clip><near>0.6</near><far>6</far></clip></depth_camera>
          <image><width>1280</width><height>720</height><format>R8G8B8</format></image>
          <clip><near>0.1</near><far>100</far></clip>
        </camera>

        <plugin name='d455_depth_camera_controller' filename='libgazebo_ros_depth_camera.so'>
          <ros><namespace>/d455/depth</namespace></ros>
          <frame_name>camera_d455_depth_optical_frame</frame_name>
          <depth_image_topic_name>/d455/depth/image_raw</depth_image_topic_name>
          <point_cloud_topic_name>/d455/depth/points</point_cloud_topic_name>
          <depth_image_camera_info_topic_name>/d455/depth/camera_info</depth_image_camera_info_topic_name>
          <point_cloud>1</point_cloud>
        </plugin>
      </sensor>

      <sensor name='d455_imu' type='imu'>
        <always_on>1</always_on>
        <update_rate>200</update_rate>
        <pose>-0.52457 0 0.42892 0 -0 0</pose>
        <plugin name='d455_imu_controller' filename='libgazebo_ros_imu_sensor.so'>
          <ros><namespace>/d455/imu</namespace></ros>
          <frame_name>camera_d455_imu_frame</frame_name>
          <topic_name>/d455/imu/data_raw</topic_name>
          <gaussian_noise>0.0005</gaussian_noise>
        </plugin>
      </sensor>

      <!-- base_footprint_fixed_joint_lump__d435i_collision_collision_1 -->
      <!--base_footprint_fixed_joint_lump__d435i_visual_visual_1 -->
      <collision name='d435i_collision_1'>
        <pose>0.04512 0 1.77259 0 1.0472 0</pose>
        <geometry>
          <box>
            <size>0.09 0.025 0.025</size>
          </box>
        </geometry>
      </collision>

      <visual name='d435i_visual_1'>
        <pose>0.04512 0 1.77259 0 1.0472 0</pose>
        <geometry>
          <mesh>
            <scale>0.001 0.001 0.001</scale>
            <uri>model://uvc1_common/meshes/sensors/camera_d435i.dae</uri>
          </mesh>
        </geometry>
      </visual>

      <!--base_footprint_fixed_joint_lump__fisheye_front_visual_3 -->
      <!--base_footprint_fixed_joint_lump__fisheye_left_visual_4 -->
      <!--base_footprint_fixed_joint_lump__fisheye_rear_visual_5 -->
      <!--base_footprint_fixed_joint_lump__fisheye_right_visual_6 -->

      <visual name='fisheye_front_visual_3'>
        <pose>0.07 0 1.845 0 0.628 -0.0255</pose>
        <geometry>
          <sphere>
            <radius>0.00346</radius>
          </sphere>
        </geometry>
      </visual>

      <visual name='fisheye_left_visual_4'>
        <pose>-0.2 0.18 1.845 0 0.628 1.5708</pose>
        <geometry>
          <sphere>
            <radius>0.00346</radius>
          </sphere>
        </geometry>
      </visual>

      <visual name='fisheye_rear_visual_5'>
        <pose>-0.5 0 1.845 7e-06 0.628319 3.14159</pose>
        <geometry>
          <sphere>
            <radius>0.00346</radius>
          </sphere>
        </geometry>
      </visual>

      <visual name='fisheye_right_visual_6'>
        <pose>-0.2 -0.18 1.845 0 0.628 -1.5708</pose>
        <geometry>
          <sphere>
            <radius>0.00346</radius>
          </sphere>
        </geometry>
      </visual>

      <!--base_footprint_fixed_joint_lump_front_left_sonar_visual_7-->
      <!--base_footprint_fixed_joint_lump_front_right_sonar_visual_8-->
      <!--base_footprint_fixed_joint_lump_rear_sonar_visual_9-->
      <!--base_footprint_fixed_joint_lump_side_left_sonar_visual_10-->
      <!--base_footprint_fixed_joint_lump__side_right_sonar_visual_11-->
      <visual name='base_footprint_fixed_joint_lump_front_left_sonar_visual_7'>
        <pose>0.08 -0.1293 0.2115 0 1.5708 0</pose>
        <geometry>
          <sphere>
            <radius>0.00346</radius>
          </sphere>
        </geometry>
      </visual>

      <visual name='base_footprint_fixed_joint_lump_front_right_sonar_visual_8'>
        <pose>0.08 0.1337 0.21166 0 1.5708 0</pose>
        <geometry>
          <sphere>
            <radius>0.00346</radius>
          </sphere>
        </geometry>
      </visual>

      <visual name='base_footprint_fixed_joint_lump_rear_sonar_visual_9'>
        <pose>-0.54 0.01302 0.33103 0 -0 0</pose>
        <geometry>
          <sphere>
            <radius>0.00346</radius>
          </sphere>
        </geometry>
      </visual>

      <visual name='base_footprint_fixed_joint_lump_side_left_sonar_visual_10'>
        <pose>-0.34701 -0.215 0.21154 1.5708 -0 -1.5708</pose>
        <geometry>
          <sphere>
            <radius>0.00346</radius>
          </sphere>
        </geometry>
      </visual>

      <visual name='base_footprint_fixed_joint_lump__side_right_sonar_visual_11'>
        <pose>-0.34701 0.215 0.21154 -1.5708 -0 1.5708</pose>
        <geometry>
          <sphere>
            <radius>0.00346</radius>
          </sphere>
        </geometry>
      </visual>

      <!--base_footprint_fixed_joint_lump__light_1_visual_12-->
      <!--base_footprint_fixed_joint_lump__light_2_visual_13 -->
      <!--base_footprint_fixed_joint_lump__light_3_visual_14-->
      <!--base_footprint_fixed_joint_lump__light_4_visual_15-->
      <!--base_footprint_fixed_joint_lump__light_5_visual_16-->
      <!--base_footprint_fixed_joint_lump__light_6_visual_17-->
      <visual name='light_1_visual_12'>
        <pose>-0.44042 -0.07221 1.16641 0 -0 0</pose>
        <geometry>
          <cylinder>
            <length>1.32715</length>
            <radius>0.01004</radius>
          </cylinder>
        </geometry>
      </visual>

      <visual name='light_2_visual_13'>
        <pose>-0.44042 0.07284 1.16641 0 -0 0</pose>
        <geometry>
          <cylinder>
            <length>1.32715</length>
            <radius>0.01004</radius>
          </cylinder>
        </geometry>
      </visual>

      <visual name='light_3_visual_14'>
        <pose>-0.242 0.1377 1.16641 0 -0 0</pose>
        <geometry>
          <cylinder>
            <length>1.32715</length>
            <radius>0.01004</radius>
          </cylinder>
        </geometry>
      </visual>

      <visual name='light_4_visual_15'>
        <pose>-0.35875 0.1377 1.16641 0 -0 0</pose>
        <geometry>
          <cylinder>
            <length>1.32715</length>
            <radius>0.01004</radius>
          </cylinder>
        </geometry>
      </visual>

      <visual name='light_5_visual_16'>
        <pose>-0.242 -0.14053 1.16641 0 -0 0</pose>
        <geometry>
          <cylinder>
            <length>1.32715</length>
            <radius>0.01004</radius>
          </cylinder>
        </geometry>
      </visual>

      <visual name='light_6_visual_17'>
        <pose>-0.35875 -0.14053 1.16641 0 -0 0</pose>
        <geometry>
          <cylinder>
            <length>1.32715</length>
            <radius>0.01004</radius>
          </cylinder>
        </geometry>
      </visual>

    </link>

    <!-- ============================= -->
    <!-- Wheels_Lump -->
    <!-- ============================= -->

    <!-- wheel_front_left_joint-->
    <joint name='wheel_front_left_joint' type='revolute'>
      <pose relative_to='base_footprint'>0 -0.17827 0.082 0 -0 0</pose>
      <parent>base_footprint</parent>
      <child>wheel_front_left_link</child>
      <axis>
        <xyz>0 1 0</xyz>
        <limit>
          <lower>-1e+16</lower>
          <upper>1e+16</upper>
        </limit>
        <dynamics>
          <damping>0.005</damping>
          <friction>0.005</friction>
          <spring_reference>0</spring_reference>
          <spring_stiffness>0</spring_stiffness>
        </dynamics>
      </axis>
    </joint>

     <!-- wheel_front_left_link-->
    <link name='wheel_front_left_link'>
      <pose relative_to='wheel_front_left_joint'>0 0 0 0 -0 0</pose>

      <inertial>
        <pose>0 0 0 0 -0 0</pose>
        <mass>7.90271</mass>
        <inertia>
          <ixx>0.01506</ixx>
          <ixy>0</ixy>
          <ixz>0</ixz>
          <iyy>0.01506</iyy>
          <iyz>0</iyz>
          <izz>0.02704</izz>
        </inertia>
      </inertial>

      <collision name='wheel_front_left__collision'>
        <pose>0 0.00277 0 1.5708 -0 0</pose>
        <geometry>
          <cylinder>
            <length>0.04836</length>
            <radius>0.08273</radius>
          </cylinder>
        </geometry>
      </collision>

      <visual name='wheel_front_left_visual'>
        <pose>0 0 0 0 -0 0</pose>
        <geometry>
          <mesh>
            <scale>0.001 0.001 0.001</scale>
            <uri>model://uvc1_common/meshes/wheels/wheel_front_left.dae</uri>
          </mesh>
        </geometry>
      </visual>
    </link>

    <!--wheel_front_right_joint-->
    <joint name='wheel_front_right_joint' type='revolute'>
      <pose relative_to='base_footprint'>0 0.17827 0.082 0 -0 0</pose>
      <parent>base_footprint</parent>
      <child>wheel_front_right_link</child>
      <axis>
        <xyz>0 1 0</xyz>
        <limit>
          <lower>-1e+16</lower>
          <upper>1e+16</upper>
        </limit>
        <dynamics>
          <damping>0.005</damping>
          <friction>0.005</friction>
          <spring_reference>0</spring_reference>
          <spring_stiffness>0</spring_stiffness>
        </dynamics>
      </axis>
    </joint>

    <!--wheel_front_right_link-->
    <link name='wheel_front_right_link'>
      <pose relative_to='wheel_front_right_joint'>0 0 0 0 -0 0</pose>

      <inertial>
        <pose>0 0 0 0 -0 0</pose>
        <mass>7.90462</mass>
        <inertia>
          <ixx>0.01507</ixx>
          <ixy>0</ixy>
          <ixz>0</ixz>
          <iyy>0.01507</iyy>
          <iyz>0</iyz>
          <izz>0.02706</izz>
        </inertia>
      </inertial>

      <collision name='wheel_front_right_collision'>
        <pose>0 -0.00277 0 1.5708 -0 0</pose>
        <geometry>
          <cylinder>
            <length>0.04836</length>
            <radius>0.08274</radius>
          </cylinder>
        </geometry>
      </collision>

      <visual name='wheel_front_right_visual'>
        <pose>0 0 0 0 -0 0</pose>
        <geometry>
          <mesh>
            <scale>0.001 0.001 0.001</scale>
            <uri>model://uvc1_common/meshes/wheels/wheel_front_right.dae</uri>
          </mesh>
        </geometry>
      </visual>
    </link>

    <!-- wrist_rear_left_joint-->
    <joint name='wrist_rear_left_joint' type='revolute'>
      <pose relative_to='base_footprint'>-0.47 -0.16211 0.13 0 -0 0</pose>
      <parent>base_footprint</parent>
      <child>wrist_rear_left_link</child>
      <axis>
        <xyz>0 0 1</xyz>
        <limit>
          <lower>-1e+16</lower>
          <upper>1e+16</upper>
        </limit>
        <dynamics>
          <damping>0.005</damping>
          <friction>0.005</friction>
          <spring_reference>0</spring_reference>
          <spring_stiffness>0</spring_stiffness>
        </dynamics>
      </axis>
    </joint>

    <!--wrist_rear_left_link-->
    <link name='wrist_rear_left_link'>
      <pose relative_to='wrist_rear_left_joint'>0 0 0 0 -0 0</pose>

      <inertial>
        <pose>0 0 0 0 -0 0</pose>
        <mass>2</mass>
        <inertia>
          <ixx>2e-05</ixx>
          <ixy>0</ixy>
          <ixz>0</ixz>
          <iyy>2e-05</iyy>
          <iyz>0</iyz>
          <izz>2e-05</izz>
        </inertia>
      </inertial>

      <visual name='wrist_rear_left_visual'>
        <pose>0 0 0 0 -0 0</pose>
        <geometry>
          <mesh>
            <scale>0.001 0.001 0.001</scale>
            <uri>model://uvc1_common/meshes/wheels/wrist_rear_left.dae</uri>
          </mesh>
        </geometry>
      </visual>
    </link>

    <!-- wheel_rear_left_joint-->
    <joint name='wheel_rear_left_joint' type='revolute'>
      <pose relative_to='wrist_rear_left_link'>0.03802 0 -0.08 0 -0 0</pose>
      <parent>wrist_rear_left_link</parent>
      <child>wheel_rear_left_link</child>
      <axis>
        <xyz>0 1 0</xyz>
        <limit>
          <lower>-1e+16</lower>
          <upper>1e+16</upper>
        </limit>
        <dynamics>
          <damping>0.005</damping>
          <friction>0.005</friction>
          <spring_reference>0</spring_reference>
          <spring_stiffness>0</spring_stiffness>
        </dynamics>
      </axis>
    </joint>

    <!-- wheel_rear_left_link-->
    <link name='wheel_rear_left_link'>
      <pose relative_to='wheel_rear_left_joint'>0 0 0 0 -0 0</pose>

      <inertial>
        <pose>0 0 0 0 -0 0</pose>
        <mass>2.20995</mass>
        <inertia>
          <ixx>0.00166</ixx>
          <ixy>0</ixy>
          <ixz>0</ixz>
          <iyy>0.00166</iyy>
          <iyz>0</iyz>
          <izz>0.00284</izz>
        </inertia>
      </inertial>

      <collision name='wheel_rear_left_wheel_collision'>
        <pose>-3e-05 0 0 1.5708 -0 0</pose>
        <geometry>
          <cylinder>
            <length>0.03598</length>
            <radius>0.05072</radius>
          </cylinder>
        </geometry>
      </collision>

      <visual name='wheel_rear_left_visual'>
        <pose>0 0 0 0 -0 0</pose>
        <geometry>
          <mesh>
            <scale>0.001 0.001 0.001</scale>
            <uri>model://uvc1_common/meshes/wheels/wheel_rear_left.dae</uri>
          </mesh>
        </geometry>
      </visual>
    </link>

    <!--wrist_rear_right_joint-->
    <joint name='wrist_rear_right_joint' type='revolute'>
      <pose relative_to='base_footprint'>-0.47 0.16211 0.13 0 -0 0</pose>
      <parent>base_footprint</parent>
      <child>wrist_rear_right_link</child>
      <axis>
        <xyz>0 0 1</xyz>
        <limit>
          <lower>-1e+16</lower>
          <upper>1e+16</upper>
        </limit>
        <dynamics>
          <damping>0.005</damping>
          <friction>0.005</friction>
          <spring_reference>0</spring_reference>
          <spring_stiffness>0</spring_stiffness>
        </dynamics>
      </axis>
    </joint>

    <!--wrist_rear_right_link-->
    <link name='wrist_rear_right_link'>
      <pose relative_to='wrist_rear_right_joint'>0 0 0 0 -0 0</pose>

      <inertial>
        <pose>0 0 0 0 -0 0</pose>
        <mass>2</mass>
        <inertia>
          <ixx>2e-05</ixx>
          <ixy>0</ixy>
          <ixz>0</ixz>
          <iyy>2e-05</iyy>
          <iyz>0</iyz>
          <izz>2e-05</izz>
        </inertia>
      </inertial>

      <visual name='wrist_rear_right_visual'>
        <pose>0 0 0 0 -0 0</pose>
        <geometry>
          <mesh>
            <scale>0.001 0.001 0.001</scale>
            <uri>model://uvc1_common/meshes/wheels/wrist_rear_right.dae</uri>
          </mesh>
        </geometry>
      </visual>
    </link>

    <!--wheel_rear_right_joint-->
    <joint name='wheel_rear_right_joint' type='revolute'>
      <pose relative_to='wrist_rear_right_link'>0.03802 0 -0.08 0 -0 0</pose>
      <parent>wrist_rear_right_link</parent>
      <child>wheel_rear_right_link</child>
      <axis>
        <xyz>0 1 0</xyz>
        <limit>
          <lower>-1e+16</lower>
          <upper>1e+16</upper>
        </limit>
        <dynamics>
          <damping>0.005</damping>
          <friction>0.005</friction>
          <spring_reference>0</spring_reference>
          <spring_stiffness>0</spring_stiffness>
        </dynamics>
      </axis>
    </joint>

    <!--wheel_rear_right_link-->
    <link name='wheel_rear_right_link'>
      <pose relative_to='wheel_rear_right_joint'>0 0 0 0 -0 0</pose>
      <inertial>
        <pose>0 0 0 0 -0 0</pose>
        <mass>2.20995</mass>
        <inertia>
          <ixx>0.00166</ixx>
          <ixy>0</ixy>
          <ixz>0</ixz>
          <iyy>0.00166</iyy>
          <iyz>0</iyz>
          <izz>0.00284</izz>
        </inertia>
      </inertial>

      <collision name='wheel_rear_right_collision'>
        <pose>-3e-05 0 0 1.5708 -0 0</pose>
        <geometry>
          <cylinder>
            <length>0.03598</length>
            <radius>0.05072</radius>
          </cylinder>
        </geometry>
      </collision>

      <visual name='wheel_rear_right_visual'>
        <pose>0 0 0 0 -0 0</pose>
        <geometry>
          <mesh>
            <scale>0.001 0.001 0.001</scale>
            <uri>model://uvc1_common/meshes/wheels/wheel_rear_right.dae</uri>
          </mesh>
        </geometry>
      </visual>
    </link>

    <!-- ============================= -->
    <!-- DIFFERENTIAL DRIVE -->
    <!-- ============================= -->

    <plugin name="uvc1_diff_drive" filename="libgazebo_ros_diff_drive.so">
      <ros>
        <namespace>/</namespace>
      </ros>
      <!-- wheels-->
      <left_joint>wheel_front_left_joint</left_joint>
      <right_joint>wheel_front_right_joint</right_joint>
      <!--kinematics-->
      <wheel_separation>0.356</wheel_separation>
      <wheel_diameter>0.165</wheel_diameter>
      <!--control limits-->
      <max_wheel_torque>20</max_wheel_torque>
      <update_rate>100</update_rate>

      <command_topic>cmd_vel</command_topic>
      <!--odometry outputs-->
      <publish_odom>true</publish_odom>
      <publish_odom_tf>true</publish_odom_tf>
      <odometry_topic>odom</odometry_topic>
      <robot_base_frame>base_footprint</robot_base_frame>
    </plugin>

    <!-- ============================= -->
    <!-- JOINT STATE PUBLISHER -->
    <!-- ============================= -->
    <plugin name="uvc1_joint_state"
            filename="libgazebo_ros_joint_state_publisher.so">

      <ros>
        <remapping>~/out:=joint_states</remapping>
      </ros>

      <update_rate>30</update_rate>

      <joint_name>wheel_front_left_joint</joint_name>
      <joint_name>wheel_front_right_joint</joint_name>
      <joint_name>wheel_rear_left_joint</joint_name>
      <joint_name>wheel_rear_right_joint</joint_name>

    </plugin>

  </model>
</sdf>
